Workbook

Sheet Cover
A1: Apple Inc. (NASDAQ: AAPL)
A2: 3-Statement Financial Model & DCF Valuation
A3: Model date: September 21, 2026 | Price date: Sep 18, 2026 close | $ in billions unless noted | Fiscal year ends last Saturday of September
A5: Tab | B5: What it does
A6: Assumptions | B6: Every forecast driver in one place (blue = input), with the rationale for each. Market inputs for the DCF.
A7: Income Statement | B7: Revenue → Gross profit → EBIT → Net income. FY2022A–FY2025A actuals; FY2026E–FY2031E forecast.
A8: Balance Sheet | B8: Simplified balance sheet. Balances every year (check row = 0). Memo: NWC and change in NWC.
A9: Cash Flow Statement | B9: Net income + non-cash items − ΔNWC − CapEx ± financing = change in cash → ending cash links to the Balance Sheet.
A10: UFCF | B10: EBIT × (1 − t) + D&A − CapEx − ΔNWC for FY2027E–FY2031E.
A11: DCF | B11: Discount UFCF at WACC, Gordon Growth terminal value, EV → Equity value → implied share price, reverse DCF.
A12: WACC | B12: CAPM cost of equity, after-tax cost of debt, market-value weights.
A13: Sensitivity Analysis | B13: Implied share price across WACC (8.5%–10.5%) and terminal growth (2.0%–4.0%).
A14: Valuation Summary | B14: One-page output and interpretation.
A16: Colour code
A17: 1,234.5 | B17: Blue = hard-coded input (historical data or forecast assumption)
A18: 1,234.5 | B18: Black = formula on the same sheet
A19: 1,234.5 | B19: Green = link to another sheet
B20: Yellow fill = key assumption / key output
A22: Key conventions
A23: • Historical period FY2022–FY2025 from Apple's audited results (Q4 earnings releases / Form 10-K). FY2026E combines 9 months reported (to Jun 27, 2026) with Q4 guidance.
A24: • Valuation date ≈ FY2026 year-end (Sep 26, 2026, five days after the model date). The five DCF years are FY2027E–FY2031E, discounted t = 1…5 (end-of-year convention).
A25: • 'Cash' = cash & equivalents + current and non-current marketable securities. The EV → Equity bridge uses the latest reported balance sheet (Jun 27, 2026).
A26: • Share-based compensation is added back in operating cash flow (it is non-cash) but NOT in UFCF (conservative: it is a real cost to shareholders via dilution).
A27: • Other non-current assets and liabilities are held flat; no circular interest calculation. Checks: Balance Sheet balances and CFS cash = BS cash in every forecast year.
A29: Sources
A30: Apple FY2025 Q4 financial statements: https://www.apple.com/newsroom/pdfs/fy2025-q4/FY25_Q4_Consolidated_Financial_Statements.pdf
A31: Apple FY2023 Q4 financial statements (FY2022–FY2023): https://www.apple.com/newsroom/pdfs/fy2023-q4/FY23_Q4_Consolidated_Financial_Statements.pdf
A32: Apple FY2026 Q3 financial statements: https://www.apple.com/newsroom/pdfs/fy2026q3/FY26_Q3_Consolidated_Financial_Statements.pdf
A33: Q4 FY2026 guidance (revenue +9–11% YoY, GM 47–48%): Apple Q3 FY26 earnings call, Jul 30, 2026 (via Investing.com / CNBC coverage)
A34: 10-yr Treasury: US Treasury / FRED DGS10 (~5.0%, Sep 18–21, 2026). ERP: Damodaran implied ERP, Jan 2026 (4.23%). Share price: Yahoo Finance, Sep 18, 2026 close.

Sheet Assumptions
A1: Apple Inc. (AAPL) — Assumptions
A2: Historical columns are calculated from the statements (black/green). Forecast columns are inputs (blue, yellow = key driver). Change the blue cells only.
B3: Historical — SEC filings | F3: Current yr est. | G3: Forecast (DCF years 1–5)
B4: FY2022A | C4: FY2023A | D4: FY2024A | E4: FY2025A | F4: FY2026E | G4: FY2027E | H4: FY2028E | I4: FY2029E | J4: FY2030E | K4: FY2031E | L4: Notes / rationale / source
A5: Revenue & margins
A6: Revenue growth | B6: ='Income Statement'!B6 -> 0.077937876 | C6: ='Income Statement'!C6 -> -0.028004605 | D6: ='Income Statement'!D6 -> 0.020219941 | E6: ='Income Statement'!E6 -> 0.064255118 | F6: 0.146 | G6: 0.06 | H6: 0.05 | I6: 0.045 | J6: 0.04 | K6: 0.035 | L6: FY26E: 9M reported $364.4B (+16%) + Q4 guided +9–11% YoY → ~14.6%. FY27E drops to 6% (tough comp after iPhone 17 cycle; consensus single-digit). Then fades toward 3% terminal as hardware matures.
A7: Gross margin | B7: ='Income Statement'!B9 -> 0.43309631 | C7: ='Income Statement'!C9 -> 0.4413113 | D7: ='Income Statement'!D9 -> 0.4620635 | E7: ='Income Statement'!E9 -> 0.46905164 | F7: 0.487 | G7: 0.475 | H7: 0.4775 | I7: 0.48 | J7: 0.4825 | K7: 0.485 | L7: FY26E: 9M 49.1% (incl. tariff refunds) + Q4 guide 47–48%. FY27E resets to 47.5% (no refunds, memory costs). Then +25bp/yr from Services mix (Services GM ~75% vs Products ~37% in FY25).
A8: R&D % of revenue | B8: ='Income Statement'!B10/'Income Statement'!B5 -> 0.066571484 | C8: ='Income Statement'!C10/'Income Statement'!C5 -> 0.078048971 | D8: ='Income Statement'!D10/'Income Statement'!D5 -> 0.080222998 | E8: ='Income Statement'!E10/'Income Statement'!E5 -> 0.083020754 | F8: 0.096 | G8: 0.096 | H8: 0.096 | I8: 0.096 | J8: 0.096 | K8: 0.096 | L8: Rising with AI investment: 6.7% (FY22) → 8.3% (FY25) → 9.3% (9M FY26). Held at 9.6%.
A9: SG&A % of revenue | B9: ='Income Statement'!B11/'Income Statement'!B5 -> 0.063637378 | C9: ='Income Statement'!C11/'Income Statement'!C5 -> 0.065048202 | D9: ='Income Statement'!D11/'Income Statement'!D5 -> 0.066738272 | E9: ='Income Statement'!E11/'Income Statement'!E5 -> 0.066322889 | F9: 0.062 | G9: 0.062 | H9: 0.062 | I9: 0.062 | J9: 0.062 | K9: 0.062 | L9: Stable ~6–7%. 9M FY26 was 6.1%; operating leverage keeps it ~6.2%.
A10: EBIT margin (memo = GM − R&D% − SG&A%) | B10: ='Income Statement'!B14 -> 0.30288744 | C10: ='Income Statement'!C14 -> 0.29821412 | D10: ='Income Statement'!D14 -> 0.31510223 | E10: ='Income Statement'!E14 -> 0.319708 | F10: =F7-F8-F9 -> 0.329 | G10: =G7-G8-G9 -> 0.317 | H10: =H7-H8-H9 -> 0.3195 | I10: =I7-I8-I9 -> 0.322 | J10: =J7-J8-J9 -> 0.3245 | K10: =K7-K8-K9 -> 0.327 | L10: Output, not an input: margin expands only slowly (~25bp/yr) via mix.
A11: Other income / (expense), net ($B) | B11: ='Income Statement'!B15 -> -0.334 | C11: ='Income Statement'!C15 -> -0.565 | D11: ='Income Statement'!D15 -> 0.269 | E11: ='Income Statement'!E15 -> -0.321 | F11: 0.9 | G11: 0 | H11: 0 | I11: 0 | J11: 0 | K11: 0 | L11: FY26E: 9M actual +$0.67B. Forecast $0: interest income ≈ interest expense for Apple; avoids a circular interest calculation.
A12: Effective tax rate | B12: ='Income Statement'!B18 -> 0.16204462 | C12: ='Income Statement'!C18 -> 0.14719174 | D12: ='Income Statement'!D18 -> 0.24091185 | E12: ='Income Statement'!E18 -> 0.15610002 | F12: 0.176 | G12: 0.17 | H12: 0.17 | I12: 0.17 | J12: 0.17 | K12: 0.17 | L12: FY25 15.6% (FY24 inflated by one-time EU charge). 9M FY26 17.6%. 17% long-term (global minimum tax).
A14: Cash flow drivers (% of revenue)
A15: D&A % of revenue | B15: ='Cash Flow Statement'!B7/'Income Statement'!B5 -> 0.028159299 | C15: ='Cash Flow Statement'!C7/'Income Statement'!C5 -> 0.030053355 | D15: ='Cash Flow Statement'!D7/'Income Statement'!D5 -> 0.02926848 | E15: ='Cash Flow Statement'!E7/'Income Statement'!E5 -> 0.028109313 | F15: 0.0275 | G15: 0.028 | H15: 0.028 | I15: 0.028 | J15: 0.028 | K15: 0.028 | L15: Historically 2.7–3.0%. 9M FY26 2.7%.
A16: CapEx % of revenue | B16: =-'Cash Flow Statement'!B13/'Income Statement'!B5 -> 0.027155059 | C16: =-'Cash Flow Statement'!C13/'Income Statement'!C5 -> 0.028592301 | D16: =-'Cash Flow Statement'!D13/'Income Statement'!D5 -> 0.024158963 | E16: =-'Cash Flow Statement'!E13/'Income Statement'!E5 -> 0.030553079 | F16: 0.023 | G16: 0.03 | H16: 0.03 | I16: 0.03 | J16: 0.03 | K16: 0.03 | L16: 9M FY26 only 1.9%; FY26E 2.3%. 3.0% thereafter for AI / Private Cloud Compute servers & data centers — above D&A so PP&E grows.
A17: Share-based comp % of revenue | B17: ='Cash Flow Statement'!B8/'Income Statement'!B5 -> 0.022920006 | C17: ='Cash Flow Statement'!C8/'Income Statement'!C5 -> 0.028263564 | D17: ='Cash Flow Statement'!D8/'Income Statement'!D5 -> 0.029889908 | E17: ='Cash Flow Statement'!E8/'Income Statement'!E5 -> 0.030908711 | F17: 0.03 | G17: 0.03 | H17: 0.03 | I17: 0.03 | J17: 0.03 | K17: 0.03 | L17: ~3% of revenue. Non-cash add-back in CFO; treated as a real cost in UFCF (not added back).
A19: Working capital (% of revenue, year-end)
A20: Accounts receivable | B20: ='Balance Sheet'!B7/'Income Statement'!B5 -> 0.071473494 | C20: ='Balance Sheet'!C7/'Income Statement'!C5 -> 0.076987098 | D20: ='Balance Sheet'!D7/'Income Statement'!D5 -> 0.085439922 | E20: ='Balance Sheet'!E7/'Income Statement'!E5 -> 0.095580797 | F20: =$E20 -> 0.095580797 | G20: =$E20 -> 0.095580797 | H20: =$E20 -> 0.095580797 | I20: =$E20 -> 0.095580797 | J20: =$E20 -> 0.095580797 | K20: =$E20 -> 0.095580797 | L20: All WC ratios held at FY2025 levels (latest year; avoids an artificial one-time cash swing).
A21: Inventory | B21: ='Balance Sheet'!B8/'Income Statement'!B5 -> 0.012542858 | C21: ='Balance Sheet'!C8/'Income Statement'!C5 -> 0.016517735 | D21: ='Balance Sheet'!D8/'Income Statement'!D5 -> 0.018632603 | E21: ='Balance Sheet'!E8/'Income Statement'!E5 -> 0.013739875 | F21: =$E21 -> 0.013739875 | G21: =$E21 -> 0.013739875 | H21: =$E21 -> 0.013739875 | I21: =$E21 -> 0.013739875 | J21: =$E21 -> 0.013739875 | K21: =$E21 -> 0.013739875
A22: Other current assets | B22: ='Balance Sheet'!B9/'Income Statement'!B5 -> 0.13686829 | C22: ='Balance Sheet'!C9/'Income Statement'!C5 -> 0.12046388 | D22: ='Balance Sheet'!D9/'Income Statement'!D5 -> 0.12050072 | E22: ='Balance Sheet'!E9/'Income Statement'!E5 -> 0.11477529 | F22: =$E22 -> 0.11477529 | G22: =$E22 -> 0.11477529 | H22: =$E22 -> 0.11477529 | I22: =$E22 -> 0.11477529 | J22: =$E22 -> 0.11477529 | K22: =$E22 -> 0.11477529
A23: Accounts payable | B23: ='Balance Sheet'!B15/'Income Statement'!B5 -> 0.16259307 | C23: ='Balance Sheet'!C15/'Income Statement'!C5 -> 0.16335364 | D23: ='Balance Sheet'!D15/'Income Statement'!D5 -> 0.1763525 | E23: ='Balance Sheet'!E15/'Income Statement'!E5 -> 0.16786772 | F23: =$E23 -> 0.16786772 | G23: =$E23 -> 0.16786772 | H23: =$E23 -> 0.16786772 | I23: =$E23 -> 0.16786772 | J23: =$E23 -> 0.16786772 | K23: =$E23 -> 0.16786772
A24: Other current liabilities | B24: ='Balance Sheet'!B16/'Income Statement'!B5 -> 0.174365 | C24: ='Balance Sheet'!C16/'Income Statement'!C5 -> 0.17451766 | D24: ='Balance Sheet'!D16/'Income Statement'!D5 -> 0.22134336 | E24: ='Balance Sheet'!E16/'Income Statement'!E5 -> 0.1812808 | F24: =$E24 -> 0.1812808 | G24: =$E24 -> 0.1812808 | H24: =$E24 -> 0.1812808 | I24: =$E24 -> 0.1812808 | J24: =$E24 -> 0.1812808 | K24: =$E24 -> 0.1812808
A25: NWC % of revenue (memo) | B25: =B20+B21+B22-B23-B24 -> -0.11607342 | C25: =C20+C21+C22-C23-C24 -> -0.12390258 | D25: =D20+D21+D22-D23-D24 -> -0.17312261 | E25: =E20+E21+E22-E23-E24 -> -0.12505256 | F25: =F20+F21+F22-F23-F24 -> -0.12505256 | G25: =G20+G21+G22-G23-G24 -> -0.12505256 | H25: =H20+H21+H22-H23-H24 -> -0.12505256 | I25: =I20+I21+I22-I23-I24 -> -0.12505256 | ... K25: =K20+K21+K22-K23-K24 -> -0.12505256 | L25: Negative: Apple collects from customers before it pays suppliers, so revenue growth RELEASES cash.
A27: Capital allocation ($B)
A28: Debt issuance / (repayment) | B28: ='Cash Flow Statement'!B18 -> -0.123 | C28: ='Cash Flow Statement'!C18 -> -9.901 | D28: ='Cash Flow Statement'!D18 -> -5.998 | E28: ='Cash Flow Statement'!E18 -> -8.483 | F28: -14 | G28: -5 | H28: -5 | I28: -5 | J28: -5 | K28: -5 | L28: FY26E: 9M actual net repayment $14.1B. Then −$5B/yr (partial refinancing of maturities).
A29: Dividends paid | B29: =-'Cash Flow Statement'!B19 -> 14.841 | C29: =-'Cash Flow Statement'!C19 -> 15.025 | D29: =-'Cash Flow Statement'!D19 -> 15.234 | E29: =-'Cash Flow Statement'!E19 -> 15.421 | F29: 15.7 | G29: 16 | H29: 16.3 | I29: 16.7 | J29: 17 | K29: 17.3 | L29: FY26E: 9M $11.8B + Q4 ~$3.9B. ~+2%/yr (dividend per share +4%, share count −2%).
A30: Share repurchases | B30: =-'Cash Flow Statement'!B20 -> 89.402 | C30: =-'Cash Flow Statement'!C20 -> 77.55 | D30: =-'Cash Flow Statement'!D20 -> 94.949 | E30: =-'Cash Flow Statement'!E20 -> 90.711 | F30: 88 | G30: 120 | H30: 130 | I30: 140 | J30: 145 | K30: 150 | L30: FY26E: 9M $62.1B + Q4 ~$26B. Then sized so cash stays ~stable (Apple's 'net cash neutral' goal). Buybacks do NOT change the DCF value.
A32: Valuation & market inputs
A33: Current share price ($) | B33: 336.13 | C33: AAPL close, Sep 18, 2026 (last close before model date). Source: Yahoo Finance / Investing.com.
A34: Basic shares outstanding (B) | B34: 14.608963 | C34: 14,608,963k shares at Jun 27, 2026 — Q3 FY26 balance sheet.
A35: Dilutive securities – RSUs (B) | B35: 0.058566 | C35: Q3 FY26 diluted (14,714,676k) − basic (14,656,110k) weighted shares.
A36: Diluted shares outstanding (B) | B36: =B34+B35 -> 14.667529 | C36: Basic + dilution.
A37: Cash & cash equivalents | B37: 39.544 | C37: Latest reported balance sheet: Jun 27, 2026 (Q3 FY26).
A38: Marketable securities – current | B38: 22.855 | C38: Jun 27, 2026.
A39: Marketable securities – non-current | B39: 84.118 | C39: Jun 27, 2026.
A40: Total cash & marketable securities | B40: =SUM(B37:B39) -> 146.517 | C40: Used in the EV → Equity bridge.
A41: Commercial paper | B41: 1.997 | C41: Jun 27, 2026.
A42: Term debt – current | B42: 11.007 | C42: Jun 27, 2026.
A43: Term debt – non-current | B43: 71.34 | C43: Jun 27, 2026.
A44: Total debt | B44: =SUM(B41:B43) -> 84.344 | C44: Used in the EV → Equity bridge and WACC weights.
...

Sheet Income Statement
A1: Apple Inc. (AAPL) — Income Statement
A2: $ in billions | Fiscal year ends last Saturday of September | Blue = hard-coded historical input, Black = formula, Green = link to another sheet
B3: Historical — SEC filings | F3: Current yr est. | G3: Forecast (DCF years 1–5)
B4: FY2022A | C4: FY2023A | D4: FY2024A | E4: FY2025A | F4: FY2026E | G4: FY2027E | H4: FY2028E | I4: FY2029E | J4: FY2030E | K4: FY2031E | L4: Notes / rationale / source
A5: Revenue | B5: 394.328 | C5: 383.285 | D5: 391.035 | E5: 416.161 | F5: =E5*(1+Assumptions!F6) -> 476.92051 | G5: =F5*(1+Assumptions!G6) -> 505.53574 | H5: =G5*(1+Assumptions!H6) -> 530.81252 | I5: =H5*(1+Assumptions!I6) -> 554.69909 | J5: =I5*(1+Assumptions!J6) -> 576.88705 | K5: =J5*(1+Assumptions!K6) -> 597.0781 | L5: Hist: Form 10-K / Q4 earnings release. Forecast: prior-year revenue × (1 + growth assumption).
A6: % growth | B6: =B5/365.817-1 -> 0.077937876 | C6: =C5/B5-1 -> -0.028004605 | D6: =D5/C5-1 -> 0.020219941 | E6: =E5/D5-1 -> 0.064255118 | F6: =F5/E5-1 -> 0.146 | G6: =G5/F5-1 -> 0.06 | H6: =H5/G5-1 -> 0.05 | I6: =I5/H5-1 -> 0.045 | J6: =J5/I5-1 -> 0.04 | K6: =K5/J5-1 -> 0.035 | L6: FY2022 growth vs FY2021 revenue of $365.817B (FY2022 Form 10-K).
A7: Cost of revenue | B7: 223.546 | C7: 214.137 | D7: 210.352 | E7: 220.96 | F7: =F5-F8 -> 244.66022 | G7: =G5-G8 -> 265.40626 | H7: =H5-H8 -> 277.34954 | I7: =I5-I8 -> 288.44353 | J7: =J5-J8 -> 298.53905 | K7: =K5-K8 -> 307.49522 | L7: Forecast: Revenue − Gross profit.
A8: Gross profit | B8: =B5-B7 -> 170.782 | C8: =C5-C7 -> 169.148 | D8: =D5-D7 -> 180.683 | E8: =E5-E7 -> 195.201 | F8: =F5*Assumptions!F7 -> 232.26029 | G8: =G5*Assumptions!G7 -> 240.12947 | H8: =H5*Assumptions!H7 -> 253.46298 | I8: =I5*Assumptions!I7 -> 266.25556 | J8: =J5*Assumptions!J7 -> 278.348 | K8: =K5*Assumptions!K7 -> 289.58288 | L8: Hist: Revenue − COGS. Forecast: Revenue × Gross margin assumption.
A9: % gross margin | B9: =B8/B5 -> 0.43309631 | C9: =C8/C5 -> 0.4413113 | D9: =D8/D5 -> 0.4620635 | E9: =E8/E5 -> 0.46905164 | F9: =F8/F5 -> 0.487 | G9: =G8/G5 -> 0.475 | H9: =H8/H5 -> 0.4775 | I9: =I8/I5 -> 0.48 | ... K9: =K8/K5 -> 0.485
A10: Research & development | B10: 26.251 | C10: 29.915 | D10: 31.37 | E10: 34.55 | F10: =F5*Assumptions!F8 -> 45.784369 | G10: =G5*Assumptions!G8 -> 48.531431 | H10: =H5*Assumptions!H8 -> 50.958002 | I10: =I5*Assumptions!I8 -> 53.251112 | J10: =J5*Assumptions!J8 -> 55.381157 | K10: =K5*Assumptions!K8 -> 57.319497 | L10: Forecast: Revenue × R&D % of revenue.
A11: Selling, general & administrative | B11: 25.094 | C11: 24.932 | D11: 26.097 | E11: 27.601 | F11: =F5*Assumptions!F9 -> 29.569071 | G11: =G5*Assumptions!G9 -> 31.343216 | H11: =H5*Assumptions!H9 -> 32.910376 | I11: =I5*Assumptions!I9 -> 34.391343 | J11: =J5*Assumptions!J9 -> 35.766997 | K11: =K5*Assumptions!K9 -> 37.018842 | L11: Forecast: Revenue × SG&A % of revenue.
A12: Total operating expenses | B12: =B10+B11 -> 51.345 | C12: =C10+C11 -> 54.847 | D12: =D10+D11 -> 57.467 | E12: =E10+E11 -> 62.151 | F12: =F10+F11 -> 75.35344 | G12: =G10+G11 -> 79.874646 | H12: =H10+H11 -> 83.868379 | I12: =I10+I11 -> 87.642456 | ... K12: =K10+K11 -> 94.338339
A13: EBIT (operating income) | B13: =B8-B12 -> 119.437 | C13: =C8-C12 -> 114.301 | D13: =D8-D12 -> 123.216 | E13: =E8-E12 -> 133.05 | F13: =F8-F12 -> 156.90685 | G13: =G8-G12 -> 160.25483 | H13: =H8-H12 -> 169.5946 | I13: =I8-I12 -> 178.61311 | ... K13: =K8-K12 -> 195.24454 | L13: EBIT = Gross profit − Operating expenses. Ties to reported operating income every historical year.
A14: % EBIT margin | B14: =B13/B5 -> 0.30288744 | C14: =C13/C5 -> 0.29821412 | D14: =D13/D5 -> 0.31510223 | E14: =E13/E5 -> 0.319708 | F14: =F13/F5 -> 0.329 | G14: =G13/G5 -> 0.317 | H14: =H13/H5 -> 0.3195 | I14: =I13/I5 -> 0.322 | ... K14: =K13/K5 -> 0.327
A15: Other income / (expense), net | B15: -0.334 | C15: -0.565 | D15: 0.269 | E15: -0.321 | F15: =Assumptions!F11 -> 0.9 | G15: =Assumptions!G11 -> 0 | H15: =Assumptions!H11 -> 0 | I15: =Assumptions!I11 -> 0 | J15: =Assumptions!J11 -> 0 | K15: =Assumptions!K11 -> 0 | L15: Net interest & investment income less interest expense and other. Small for Apple; forecast set in Assumptions.
A16: Pre-tax income | B16: =B13+B15 -> 119.103 | C16: =C13+C15 -> 113.736 | D16: =D13+D15 -> 123.485 | E16: =E13+E15 -> 132.729 | F16: =F13+F15 -> 157.80685 | G16: =G13+G15 -> 160.25483 | H16: =H13+H15 -> 169.5946 | I16: =I13+I15 -> 178.61311 | ... K16: =K13+K15 -> 195.24454
A17: Income taxes | B17: 19.3 | C17: 16.741 | D17: 29.749 | E17: 20.719 | F17: =F16*Assumptions!F12 -> 27.774005 | G17: =G16*Assumptions!G12 -> 27.243321 | H17: =H16*Assumptions!H12 -> 28.831082 | I17: =I16*Assumptions!I12 -> 30.364228 | J17: =J16*Assumptions!J12 -> 31.823974 | K17: =K16*Assumptions!K12 -> 33.191571 | L17: FY2024 includes a one-time $10.2B charge (EU State Aid decision). Forecast: Pre-tax income × tax rate.
A18: % effective tax rate | B18: =B17/B16 -> 0.16204462 | C18: =C17/C16 -> 0.14719174 | D18: =D17/D16 -> 0.24091185 | E18: =E17/E16 -> 0.15610002 | F18: =F17/F16 -> 0.176 | G18: =G17/G16 -> 0.17 | H18: =H17/H16 -> 0.17 | I18: =I17/I16 -> 0.17 | ... K18: =K17/K16 -> 0.17
A19: Net income | B19: =B16-B17 -> 99.803 | C19: =C16-C17 -> 96.995 | D19: =D16-D17 -> 93.736 | E19: =E16-E17 -> 112.01 | F19: =F16-F17 -> 130.03284 | G19: =G16-G17 -> 133.01151 | H19: =H16-H17 -> 140.76352 | I19: =I16-I17 -> 148.24888 | ... K19: =K16-K17 -> 162.05297 | L19: Ties to reported net income: FY22 $99.803B, FY23 $96.995B, FY24 $93.736B, FY25 $112.010B.
A20: % net margin | B20: =B19/B5 -> 0.25309641 | C20: =C19/C5 -> 0.25306234 | D20: =D19/D5 -> 0.23971256 | E20: =E19/E5 -> 0.26915064 | F20: =F19/F5 -> 0.27265098 | G20: =G19/G5 -> 0.26311 | H20: =H19/H5 -> 0.265185 | I20: =I19/I5 -> 0.26726 | ... K20: =K19/K5 -> 0.27141
A22: Memo
A23: D&A (from Cash Flow Statement) | B23: ='Cash Flow Statement'!B7 -> 11.104 | C23: ='Cash Flow Statement'!C7 -> 11.519 | D23: ='Cash Flow Statement'!D7 -> 11.445 | E23: ='Cash Flow Statement'!E7 -> 11.698 | F23: ='Cash Flow Statement'!F7 -> 13.115314 | G23: ='Cash Flow Statement'!G7 -> 14.155001 | H23: ='Cash Flow Statement'!H7 -> 14.862751 | I23: ='Cash Flow Statement'!I7 -> 15.531574 | ... K23: ='Cash Flow Statement'!K7 -> 16.718187
A24: EBITDA | B24: =B13+B23 -> 130.541 | C24: =C13+C23 -> 125.82 | D24: =D13+D23 -> 134.661 | E24: =E13+E23 -> 144.748 | F24: =F13+F23 -> 170.02216 | G24: =G13+G23 -> 174.40983 | H24: =H13+H23 -> 184.45735 | I24: =I13+I23 -> 194.14468 | ... K24: =K13+K23 -> 211.96272 | L24: EBITDA = EBIT + D&A (non-cash charge added back).
A25: % EBITDA margin | B25: =B24/B5 -> 0.33104674 | C25: =C24/C5 -> 0.32826748 | D25: =D24/D5 -> 0.34437071 | E25: =E24/E5 -> 0.34781731 | F25: =F24/F5 -> 0.3565 | G25: =G24/G5 -> 0.345 | H25: =H24/H5 -> 0.3475 | I25: =I24/I5 -> 0.35 | ... K25: =K24/K5 -> 0.355

Sheet Balance Sheet
A1: Apple Inc. (AAPL) — Balance Sheet (simplified)
A2: $ in billions | Year-end balances | Line items aggregated from the reported balance sheet (see notes)
B3: Historical — SEC filings | F3: Current yr est. | G3: Forecast (DCF years 1–5)
B4: FY2022A | C4: FY2023A | D4: FY2024A | E4: FY2025A | F4: FY2026E | G4: FY2027E | H4: FY2028E | I4: FY2029E | J4: FY2030E | K4: FY2031E | L4: Notes / rationale / source
A5: Assets
A6: Cash & marketable securities | B6: =23.646+24.658+120.805 -> 169.109 | C6: =29.965+31.59+100.544 -> 162.099 | D6: =29.943+35.228+91.479 -> 156.65 | E6: =35.934+18.763+77.723 -> 132.42 | F6: ='Cash Flow Statement'!F26 -> 168.80473 | G6: ='Cash Flow Statement'!G26 -> 178.54965 | H6: ='Cash Flow Statement'!H26 -> 186.03684 | I6: ='Cash Flow Statement'!I26 -> 191.10437 | J6: ='Cash Flow Statement'!J26 -> 198.40774 | K6: ='Cash Flow Statement'!K26 -> 207.40384 | L6: Hist = cash & equivalents + current and non-current marketable securities (Apple manages these as one liquidity pool). Forecast = ending cash from CFS.
A7: Accounts receivable | B7: 28.184 | C7: 29.508 | D7: 33.41 | E7: 39.777 | F7: ='Income Statement'!F5*Assumptions!F20 -> 45.584442 | G7: ='Income Statement'!G5*Assumptions!G20 -> 48.319509 | H7: ='Income Statement'!H5*Assumptions!H20 -> 50.735484 | I7: ='Income Statement'!I5*Assumptions!I20 -> 53.018581 | J7: ='Income Statement'!J5*Assumptions!J20 -> 55.139324 | K7: ='Income Statement'!K5*Assumptions!K20 -> 57.0692 | L7: Trade receivables. Forecast: Revenue × AR %.
A8: Inventory | B8: 4.946 | C8: 6.331 | D8: 7.286 | E8: 5.718 | F8: ='Income Statement'!F5*Assumptions!F21 -> 6.552828 | G8: ='Income Statement'!G5*Assumptions!G21 -> 6.9459977 | H8: ='Income Statement'!H5*Assumptions!H21 -> 7.2932976 | I8: ='Income Statement'!I5*Assumptions!I21 -> 7.621496 | J8: ='Income Statement'!J5*Assumptions!J21 -> 7.9263558 | K8: ='Income Statement'!K5*Assumptions!K21 -> 8.2037782 | L8: Forecast: Revenue × Inventory %.
A9: Other current assets | B9: =32.748+21.223 -> 53.971 | C9: =31.477+14.695 -> 46.172 | D9: =32.833+14.287 -> 47.12 | E9: =33.18+14.585 -> 47.765 | F9: ='Income Statement'!F5*Assumptions!F22 -> 54.73869 | G9: ='Income Statement'!G5*Assumptions!G22 -> 58.023011 | H9: ='Income Statement'!H5*Assumptions!H22 -> 60.924162 | I9: ='Income Statement'!I5*Assumptions!I22 -> 63.665749 | J9: ='Income Statement'!J5*Assumptions!J22 -> 66.212379 | K9: ='Income Statement'!K5*Assumptions!K22 -> 68.529813 | L9: Vendor non-trade receivables + other current assets. Forecast: Revenue × %.
A10: PP&E, net | B10: 42.117 | C10: 43.715 | D10: 45.68 | E10: 49.834 | F10: =E10-'Cash Flow Statement'!F13-'Cash Flow Statement'!F7 -> 47.687858 | G10: =F10-'Cash Flow Statement'!G13-'Cash Flow Statement'!G7 -> 48.698929 | H10: =G10-'Cash Flow Statement'!H13-'Cash Flow Statement'!H7 -> 49.760554 | I10: =H10-'Cash Flow Statement'!I13-'Cash Flow Statement'!I7 -> 50.869952 | J10: =I10-'Cash Flow Statement'!J13-'Cash Flow Statement'!J7 -> 52.023727 | K10: =J10-'Cash Flow Statement'!K13-'Cash Flow Statement'!K7 -> 53.217883 | L10: Forecast: Prior PP&E + CapEx − D&A (CapEx is negative on the CFS, so it is subtracted to add it back).
A11: Other non-current assets | B11: 54.428 | C11: 64.758 | D11: 74.834 | E11: 83.727 | F11: =E11 -> 83.727 | G11: =F11 -> 83.727 | H11: =G11 -> 83.727 | I11: =H11 -> 83.727 | J11: =I11 -> 83.727 | K11: =J11 -> 83.727 | L11: Deferred tax assets, intangibles, etc. Held flat (simplification).
A12: Total assets | B12: =SUM(B6:B11) -> 352.755 | C12: =SUM(C6:C11) -> 352.583 | D12: =SUM(D6:D11) -> 364.98 | E12: =SUM(E6:E11) -> 359.241 | F12: =SUM(F6:F11) -> 407.09555 | G12: =SUM(G6:G11) -> 424.26409 | H12: =SUM(H6:H11) -> 438.47734 | I12: =SUM(I6:I11) -> 450.00715 | ... K12: =SUM(K6:K11) -> 478.15151 | L12: Ties to reported total assets: FY22 $352.755B, FY23 $352.583B, FY24 $364.980B, FY25 $359.241B.
A14: Liabilities & shareholders' equity
A15: Accounts payable | B15: 64.115 | C15: 62.611 | D15: 68.96 | E15: 69.86 | F15: ='Income Statement'!F5*Assumptions!F23 -> 80.05956 | G15: ='Income Statement'!G5*Assumptions!G23 -> 84.863134 | H15: ='Income Statement'!H5*Assumptions!H23 -> 89.10629 | I15: ='Income Statement'!I5*Assumptions!I23 -> 93.116073 | J15: ='Income Statement'!J5*Assumptions!J23 -> 96.840716 | K15: ='Income Statement'!K5*Assumptions!K23 -> 100.23014 | L15: Forecast: Revenue × AP %.
A16: Other current liabilities | B16: =60.845+7.912 -> 68.757 | C16: =58.829+8.061 -> 66.89 | D16: =78.304+8.249 -> 86.553 | E16: =66.387+9.055 -> 75.442 | F16: ='Income Statement'!F5*Assumptions!F24 -> 86.456532 | G16: ='Income Statement'!G5*Assumptions!G24 -> 91.643924 | H16: ='Income Statement'!H5*Assumptions!H24 -> 96.22612 | I16: ='Income Statement'!I5*Assumptions!I24 -> 100.5563 | J16: ='Income Statement'!J5*Assumptions!J24 -> 104.57855 | K16: ='Income Statement'!K5*Assumptions!K24 -> 108.2388 | L16: Other current liabilities + deferred revenue. Forecast: Revenue × %.
A17: Total debt | B17: =9.982+11.128+98.959 -> 120.069 | C17: =5.985+9.822+95.281 -> 111.088 | D17: =9.967+10.912+85.75 -> 106.629 | E17: =7.979+12.35+78.328 -> 98.657 | F17: =E17+'Cash Flow Statement'!F18 -> 84.657 | G17: =F17+'Cash Flow Statement'!G18 -> 79.657 | H17: =G17+'Cash Flow Statement'!H18 -> 74.657 | I17: =H17+'Cash Flow Statement'!I18 -> 69.657 | J17: =I17+'Cash Flow Statement'!J18 -> 64.657 | K17: =J17+'Cash Flow Statement'!K18 -> 59.657 | L17: Commercial paper + current term debt + non-current term debt. Forecast: Prior debt + issuance/(repayment) from CFS.
A18: Other non-current liabilities | B18: 49.142 | C18: 49.848 | D18: 45.888 | E18: 41.549 | F18: =E18 -> 41.549 | G18: =F18 -> 41.549 | H18: =G18 -> 41.549 | I18: =H18 -> 41.549 | J18: =I18 -> 41.549 | K18: =J18 -> 41.549 | L18: Mainly long-term tax liabilities. Held flat (simplification).
A19: Total liabilities | B19: =SUM(B15:B18) -> 302.083 | C19: =SUM(C15:C18) -> 290.437 | D19: =SUM(D15:D18) -> 308.03 | E19: =SUM(E15:E18) -> 285.508 | F19: =SUM(F15:F18) -> 292.72209 | G19: =SUM(G15:G18) -> 297.71306 | H19: =SUM(H15:H18) -> 301.53841 | I19: =SUM(I15:I18) -> 304.87837 | ... K19: =SUM(K15:K18) -> 309.67494
A20: Shareholders' equity | B20: 50.672 | C20: 62.146 | D20: 56.95 | E20: 73.733 | F20: =E20+'Income Statement'!F19+'Cash Flow Statement'!F8+'Cash Flow Statement'!F19+'Cash Flow Statement'!F20 -> 114.37346 | G20: =F20+'Income Statement'!G19+'Cash Flow Statement'!G8+'Cash Flow Statement'!G19+'Cash Flow Statement'!G20 -> 126.55104 | H20: =G20+'Income Statement'!H19+'Cash Flow Statement'!H8+'Cash Flow Statement'!H19+'Cash Flow Statement'!H20 -> 136.93893 | I20: =H20+'Income Statement'!I19+'Cash Flow Statement'!I8+'Cash Flow Statement'!I19+'Cash Flow Statement'!I20 -> 145.12878 | J20: =I20+'Income Statement'!J19+'Cash Flow Statement'!J8+'Cash Flow Statement'!J19+'Cash Flow Statement'!J20 -> 155.81127 | K20: =J20+'Income Statement'!K19+'Cash Flow Statement'!K8+'Cash Flow Statement'!K19+'Cash Flow Statement'!K20 -> 168.47658 | L20: Forecast: Prior equity + Net income + SBC − Dividends − Buybacks (dividends/buybacks are negative on the CFS).
A21: Total liabilities & equity | B21: =B19+B20 -> 352.755 | C21: =C19+C20 -> 352.583 | D21: =D19+D20 -> 364.98 | E21: =E19+E20 -> 359.241 | F21: =F19+F20 -> 407.09555 | G21: =G19+G20 -> 424.26409 | H21: =H19+H20 -> 438.47734 | I21: =I19+I20 -> 450.00715 | ... K21: =K19+K20 -> 478.15151
A23: Balance check (Assets − Liabilities & equity) | B23: =ROUND(B12-B21,3) -> 0 | C23: =ROUND(C12-C21,3) -> 0 | D23: =ROUND(D12-D21,3) -> 0 | E23: =ROUND(E12-E21,3) -> 0 | F23: =ROUND(F12-F21,3) -> 0 | G23: =ROUND(G12-G21,3) -> 0 | H23: =ROUND(H12-H21,3) -> 0 | I23: =ROUND(I12-I21,3) -> 0 | ... K23: =ROUND(K12-K21,3) -> 0 | L23: Must be zero in every year.
A25: Memo: working capital & net cash
A26: Net working capital (AR + Inv + OCA − AP − OCL) | B26: =B7+B8+B9-B15-B16 -> -45.771 | C26: =C7+C8+C9-C15-C16 -> -47.49 | D26: =D7+D8+D9-D15-D16 -> -67.697 | E26: =E7+E8+E9-E15-E16 -> -52.042 | F26: =F7+F8+F9-F15-F16 -> -59.640132 | G26: =G7+G8+G9-G15-G16 -> -63.21854 | H26: =H7+H8+H9-H15-H16 -> -66.379467 | I26: =I7+I8+I9-I15-I16 -> -69.366543 | ... K26: =K7+K8+K9-K15-K16 -> -74.666147 | L26: Operating current assets − operating current liabilities (excludes cash and debt). Apple's NWC is negative: suppliers fund its operations.
A27: Change in NWC (increase = cash outflow) | C27: =C26-B26 -> -1.719 | D27: =D26-C26 -> -20.207 | E27: =E26-D26 -> 15.655 | F27: =F26-E26 -> -7.598132 | G27: =G26-F26 -> -3.5784079 | H27: =H26-G26 -> -3.160927 | I27: =I26-H26 -> -2.987076 | J27: =J26-I26 -> -2.7746617 | K27: =K26-J26 -> -2.5249422 | L27: Current-year NWC − prior-year NWC. A negative number here means NWC fell → cash released.
A28: Net cash / (debt) | B28: =B6-B17 -> 49.04 | C28: =C6-C17 -> 51.011 | D28: =D6-D17 -> 50.021 | E28: =E6-E17 -> 33.763 | F28: =F6-F17 -> 84.147731 | G28: =G6-G17 -> 98.892647 | H28: =H6-H17 -> 111.37984 | I28: =I6-I17 -> 121.44737 | ... K28: =K6-K17 -> 147.74684 | L28: Cash & marketable securities − total debt.

Sheet Cash Flow Statement
A1: Apple Inc. (AAPL) — Cash Flow Statement (simplified)
A2: $ in billions | Inflows positive, outflows negative
B3: Historical — SEC filings | F3: Current yr est. | G3: Forecast (DCF years 1–5)
B4: FY2022A | C4: FY2023A | D4: FY2024A | E4: FY2025A | F4: FY2026E | G4: FY2027E | H4: FY2028E | I4: FY2029E | J4: FY2030E | K4: FY2031E | L4: Notes / rationale / source
A5: Operating activities
A6: Net income | B6: ='Income Statement'!B19 -> 99.803 | C6: ='Income Statement'!C19 -> 96.995 | D6: ='Income Statement'!D19 -> 93.736 | E6: ='Income Statement'!E19 -> 112.01 | F6: ='Income Statement'!F19 -> 130.03284 | G6: ='Income Statement'!G19 -> 133.01151 | H6: ='Income Statement'!H19 -> 140.76352 | I6: ='Income Statement'!I19 -> 148.24888 | ... K6: ='Income Statement'!K19 -> 162.05297 | L6: From the Income Statement.
A7: Depreciation & amortization | B7: 11.104 | C7: 11.519 | D7: 11.445 | E7: 11.698 | F7: ='Income Statement'!F5*Assumptions!F15 -> 13.115314 | G7: ='Income Statement'!G5*Assumptions!G15 -> 14.155001 | H7: ='Income Statement'!H5*Assumptions!H15 -> 14.862751 | I7: ='Income Statement'!I5*Assumptions!I15 -> 15.531574 | J7: ='Income Statement'!J5*Assumptions!J15 -> 16.152837 | K7: ='Income Statement'!K5*Assumptions!K15 -> 16.718187 | L7: Non-cash expense → added back. Forecast: Revenue × D&A %.
A8: Share-based compensation | B8: 9.038 | C8: 10.833 | D8: 11.688 | E8: 12.863 | F8: ='Income Statement'!F5*Assumptions!F17 -> 14.307615 | G8: ='Income Statement'!G5*Assumptions!G17 -> 15.166072 | H8: ='Income Statement'!H5*Assumptions!H17 -> 15.924376 | I8: ='Income Statement'!I5*Assumptions!I17 -> 16.640973 | J8: ='Income Statement'!J5*Assumptions!J17 -> 17.306612 | K8: ='Income Statement'!K5*Assumptions!K17 -> 17.912343 | L8: Non-cash expense → added back in CFO. (Not added back in UFCF — see UFCF tab.)
A9: Change in working capital (hist. incl. other) | B9: 2.206 | C9: -8.804 | D9: 1.385 | E9: -25.089 | F9: =-'Balance Sheet'!F27 -> 7.598132 | G9: =-'Balance Sheet'!G27 -> 3.5784079 | H9: =-'Balance Sheet'!H27 -> 3.160927 | I9: =-'Balance Sheet'!I27 -> 2.987076 | J9: =-'Balance Sheet'!J27 -> 2.7746617 | K9: =-'Balance Sheet'!K27 -> 2.5249422 | L9: Hist = reported CFO − NI − D&A − SBC (all working-capital lines + 'other'). Forecast = −(Change in NWC) from the Balance Sheet.
A10: Cash flow from operations | B10: =SUM(B6:B9) -> 122.151 | C10: =SUM(C6:C9) -> 110.543 | D10: =SUM(D6:D9) -> 118.254 | E10: =SUM(E6:E9) -> 111.482 | F10: =SUM(F6:F9) -> 165.0539 | G10: =SUM(G6:G9) -> 165.91099 | H10: =SUM(H6:H9) -> 174.71157 | I10: =SUM(I6:I9) -> 183.4085 | ... K10: =SUM(K6:K9) -> 199.20844 | L10: Ties to reported CFO: FY22 $122.151B, FY23 $110.543B, FY24 $118.254B, FY25 $111.482B.
A12: Investing activities
A13: Capital expenditures | B13: -10.708 | C13: -10.959 | D13: -9.447 | E13: -12.715 | F13: =-'Income Statement'!F5*Assumptions!F16 -> -10.969172 | G13: =-'Income Statement'!G5*Assumptions!G16 -> -15.166072 | H13: =-'Income Statement'!H5*Assumptions!H16 -> -15.924376 | I13: =-'Income Statement'!I5*Assumptions!I16 -> -16.640973 | J13: =-'Income Statement'!J5*Assumptions!J16 -> -17.306612 | K13: =-'Income Statement'!K5*Assumptions!K16 -> -17.912343 | L13: Payments for PP&E. Forecast: −Revenue × CapEx %.
A14: Other investing (incl. net marketable securities) | B14: -11.646 | C14: 14.664 | D14: 12.382 | E14: 27.91 | F14: 0 | G14: 0 | H14: 0 | I14: 0 | J14: 0 | K14: 0 | L14: Hist: net purchases/sales of marketable securities + other. Forecast: 0 because securities are already inside 'Cash & marketable securities'.
A15: Cash flow from investing | B15: =B13+B14 -> -22.354 | C15: =C13+C14 -> 3.705 | D15: =D13+D14 -> 2.935 | E15: =E13+E14 -> 15.195 | F15: =F13+F14 -> -10.969172 | G15: =G13+G14 -> -15.166072 | H15: =H13+H14 -> -15.924376 | I15: =I13+I14 -> -16.640973 | ... K15: =K13+K14 -> -17.912343
A17: Financing activities
A18: Debt issuance / (repayment) | B18: -0.123 | C18: -9.901 | D18: -5.998 | E18: -8.483 | F18: =Assumptions!F28 -> -14 | G18: =Assumptions!G28 -> -5 | H18: =Assumptions!H28 -> -5 | I18: =Assumptions!I28 -> -5 | J18: =Assumptions!J28 -> -5 | K18: =Assumptions!K28 -> -5 | L18: Hist: term debt issued − repaid ± net commercial paper. Forecast: from Assumptions.
A19: Dividends | B19: -14.841 | C19: -15.025 | D19: -15.234 | E19: -15.421 | F19: =-Assumptions!F29 -> -15.7 | G19: =-Assumptions!G29 -> -16 | H19: =-Assumptions!H29 -> -16.3 | I19: =-Assumptions!I29 -> -16.7 | J19: =-Assumptions!J29 -> -17 | K19: =-Assumptions!K29 -> -17.3
A20: Share repurchases | B20: -89.402 | C20: -77.55 | D20: -94.949 | E20: -90.711 | F20: =-Assumptions!F30 -> -88 | G20: =-Assumptions!G30 -> -120 | H20: =-Assumptions!H30 -> -130 | I20: =-Assumptions!I30 -> -140 | J20: =-Assumptions!J30 -> -145 | K20: =-Assumptions!K30 -> -150
A21: Other financing (incl. net share settlement) | B21: -6.383 | C21: -6.012 | D21: -5.802 | E21: -6.071 | F21: 0 | G21: 0 | H21: 0 | I21: 0 | J21: 0 | K21: 0 | L21: Taxes paid on net share settlement of RSUs + other. Forecast: 0 (simplification).
A22: Cash flow from financing | B22: =SUM(B18:B21) -> -110.749 | C22: =SUM(C18:C21) -> -108.488 | D22: =SUM(D18:D21) -> -121.983 | E22: =SUM(E18:E21) -> -120.686 | F22: =SUM(F18:F21) -> -117.7 | G22: =SUM(G18:G21) -> -141 | H22: =SUM(H18:H21) -> -151.3 | I22: =SUM(I18:I21) -> -161.7 | ... K22: =SUM(K18:K21) -> -172.3
A24: Net change in cash | B24: =B10+B15+B22 -> -10.952 | C24: =C10+C15+C22 -> 5.76 | D24: =D10+D15+D22 -> -0.794 | E24: =E10+E15+E22 -> 5.991 | F24: =F10+F15+F22 -> 36.384731 | G24: =G10+G15+G22 -> 9.7449161 | H24: =H10+H15+H22 -> 7.4871966 | I24: =I10+I15+I22 -> 5.0675284 | ... K24: =K10+K15+K22 -> 8.9960952 | L24: Hist = reported change in cash & equivalents only (FY22 −$10.952B, FY23 +$5.760B, FY24 −$0.794B, FY25 +$5.991B).
A25: Beginning cash & marketable securities | F25: ='Balance Sheet'!E6 -> 132.42 | G25: =F26 -> 168.80473 | H25: =G26 -> 178.54965 | I25: =H26 -> 186.03684 | J25: =I26 -> 191.10437 | K25: =J26 -> 198.40774 | L25: FY2026E starts from the FY2025 balance sheet.
A26: Ending cash & marketable securities | E26: ='Balance Sheet'!E6 -> 132.42 | F26: =F25+F24 -> 168.80473 | G26: =G25+G24 -> 178.54965 | H26: =H25+H24 -> 186.03684 | I26: =I25+I24 -> 191.10437 | J26: =J25+J24 -> 198.40774 | K26: =K25+K24 -> 207.40384 | L26: Ending cash = Beginning cash + Net change in cash → flows to the Balance Sheet.
A28: Memo
A29: Free cash flow (CFO + CapEx) | B29: =B10+B13 -> 111.443 | C29: =C10+C13 -> 99.584 | D29: =D10+D13 -> 108.807 | E29: =E10+E13 -> 98.767 | F29: =F10+F13 -> 154.08473 | G29: =G10+G13 -> 150.74492 | H29: =H10+H13 -> 158.7872 | I29: =I10+I13 -> 166.76753 | ... K29: =K10+K13 -> 181.2961 | L29: Levered FCF to equity holders (after interest, includes SBC add-back).
A30: Cash check (CFS ending cash − BS cash) | F30: =ROUND(F26-'Balance Sheet'!F6,3) -> 0 | G30: =ROUND(G26-'Balance Sheet'!G6,3) -> 0 | H30: =ROUND(H26-'Balance Sheet'!H6,3) -> 0 | I30: =ROUND(I26-'Balance Sheet'!I6,3) -> 0 | J30: =ROUND(J26-'Balance Sheet'!J6,3) -> 0 | K30: =ROUND(K26-'Balance Sheet'!K6,3) -> 0

Sheet UFCF
A1: Apple Inc. (AAPL) — Unlevered Free Cash Flow
A2: $ in billions | UFCF = EBIT × (1 − Tax rate) + D&A − CapEx − Change in NWC
A4: $B | B4: FY2026E (base) | C4: FY2027E | D4: FY2028E | E4: FY2029E | F4: FY2030E | G4: FY2031E | H4: Notes
A5: DCF year (t) | C5: 1 | D5: 2 | E5: 3 | F5: 4 | G5: 5 | H5: FY2026E is the base year (≈ valuation date); FY2027E–FY2031E are discounted.
A6: Revenue | B6: ='Income Statement'!F5 -> 476.92051 | C6: ='Income Statement'!G5 -> 505.53574 | D6: ='Income Statement'!H5 -> 530.81252 | E6: ='Income Statement'!I5 -> 554.69909 | F6: ='Income Statement'!J5 -> 576.88705 | G6: ='Income Statement'!K5 -> 597.0781
A7: EBIT | B7: ='Income Statement'!F13 -> 156.90685 | C7: ='Income Statement'!G13 -> 160.25483 | D7: ='Income Statement'!H13 -> 169.5946 | E7: ='Income Statement'!I13 -> 178.61311 | F7: ='Income Statement'!J13 -> 187.19985 | G7: ='Income Statement'!K13 -> 195.24454 | H7: Operating profit before interest — belongs to ALL capital providers.
A8: % EBIT margin | B8: =B7/B6 -> 0.329 | C8: =C7/C6 -> 0.317 | D8: =D7/D6 -> 0.3195 | E8: =E7/E6 -> 0.322 | F8: =F7/F6 -> 0.3245 | G8: =G7/G6 -> 0.327
A9: Tax rate | B9: =Assumptions!F12 -> 0.176 | C9: =Assumptions!G12 -> 0.17 | D9: =Assumptions!H12 -> 0.17 | E9: =Assumptions!I12 -> 0.17 | F9: =Assumptions!J12 -> 0.17 | G9: =Assumptions!K12 -> 0.17
A10: Less: tax on EBIT | B10: =-B7*B9 -> -27.615605 | C10: =-C7*C9 -> -27.243321 | D10: =-D7*D9 -> -28.831082 | E10: =-E7*E9 -> -30.364228 | F10: =-F7*F9 -> -31.823974 | G10: =-G7*G9 -> -33.191571 | H10: Taxes as if Apple had no debt (unlevered).
A11: NOPAT | B11: =B7+B10 -> 129.29124 | C11: =C7+C10 -> 133.01151 | D11: =D7+D10 -> 140.76352 | E11: =E7+E10 -> 148.24888 | F11: =F7+F10 -> 155.37587 | G11: =G7+G10 -> 162.05297 | H11: Net operating profit after tax = EBIT × (1 − t).
A12: Plus: D&A | B12: ='Cash Flow Statement'!F7 -> 13.115314 | C12: ='Cash Flow Statement'!G7 -> 14.155001 | D12: ='Cash Flow Statement'!H7 -> 14.862751 | E12: ='Cash Flow Statement'!I7 -> 15.531574 | F12: ='Cash Flow Statement'!J7 -> 16.152837 | G12: ='Cash Flow Statement'!K7 -> 16.718187 | H12: Non-cash expense, added back.
A13: Less: CapEx | B13: ='Cash Flow Statement'!F13 -> -10.969172 | C13: ='Cash Flow Statement'!G13 -> -15.166072 | D13: ='Cash Flow Statement'!H13 -> -15.924376 | E13: ='Cash Flow Statement'!I13 -> -16.640973 | F13: ='Cash Flow Statement'!J13 -> -17.306612 | G13: ='Cash Flow Statement'!K13 -> -17.912343 | H13: Cash spent on long-term assets (already negative).
A14: Less: increase in NWC | B14: ='Cash Flow Statement'!F9 -> 7.598132 | C14: ='Cash Flow Statement'!G9 -> 3.5784079 | D14: ='Cash Flow Statement'!H9 -> 3.160927 | E14: ='Cash Flow Statement'!I9 -> 2.987076 | F14: ='Cash Flow Statement'!J9 -> 2.7746617 | G14: ='Cash Flow Statement'!K9 -> 2.5249422 | H14: Equals −(Change in NWC). Positive here because Apple's negative NWC releases cash as it grows.
A15: Unlevered free cash flow (UFCF) | B15: =SUM(B11:B14) -> 139.03552 | C15: =SUM(C11:C14) -> 135.57884 | D15: =SUM(D11:D14) -> 142.86282 | E15: =SUM(E11:E14) -> 150.12656 | F15: =SUM(F11:F14) -> 156.99676 | G15: =SUM(G11:G14) -> 163.38375
A16: % growth | C16: =C15/B15-1 -> -0.02486179 | D16: =D15/C15-1 -> 0.053725026 | E16: =E15/D15-1 -> 0.050844123 | F16: =F15/E15-1 -> 0.04576276 | G16: =G15/F15-1 -> 0.04068231
A17: % UFCF margin | B17: =B15/B6 -> 0.29152765 | C17: =C15/C6 -> 0.26818845 | D17: =D15/D6 -> 0.26913988 | E17: =E15/E6 -> 0.27064504 | F17: =F15/F6 -> 0.27214471 | G17: =G15/G6 -> 0.27363883
A19: Memo: SBC (NOT added back) | B19: ='Cash Flow Statement'!F8 -> 14.307615 | C19: ='Cash Flow Statement'!G8 -> 15.166072 | D19: ='Cash Flow Statement'!H8 -> 15.924376 | E19: ='Cash Flow Statement'!I8 -> 16.640973 | F19: ='Cash Flow Statement'!J8 -> 17.306612 | G19: ='Cash Flow Statement'!K8 -> 17.912343 | H19: Conservative: SBC is a real economic cost (dilution), so it stays deducted inside EBIT.

Sheet DCF
A1: Apple Inc. (AAPL) — DCF Valuation
A2: $ in billions except per share | End-of-year discounting | Valuation date ≈ FY2026 year-end (Sep 26, 2026)
A4: WACC | B4: =WACC!B24 -> 0.095876543
A5: Terminal growth rate (g) | B5: =Assumptions!B47 -> 0.03
A7: $B | C7: FY2027E | D7: FY2028E | E7: FY2029E | F7: FY2030E | G7: FY2031E | H7: Formula
A8: Year (t) | C8: =UFCF!C5 -> 1 | D8: =UFCF!D5 -> 2 | E8: =UFCF!E5 -> 3 | F8: =UFCF!F5 -> 4 | G8: =UFCF!G5 -> 5
A9: UFCF | C9: =UFCF!C15 -> 135.57884 | D9: =UFCF!D15 -> 142.86282 | E9: =UFCF!E15 -> 150.12656 | F9: =UFCF!F15 -> 156.99676 | G9: =UFCF!G15 -> 163.38375
A10: Discount factor | C10: =1/(1+$B$4)^C8 -> 0.91251155 | D10: =1/(1+$B$4)^D8 -> 0.83267732 | E10: =1/(1+$B$4)^E8 -> 0.75982767 | F10: =1/(1+$B$4)^F8 -> 0.69335153 | G10: =1/(1+$B$4)^G8 -> 0.63269127 | H10: 1 / (1 + WACC)^t
A11: PV of UFCF | C11: =C9*C10 -> 123.71726 | D11: =D9*D10 -> 118.95863 | E11: =E9*E10 -> 114.07031 | F11: =F9*F10 -> 108.85394 | G11: =G9*G10 -> 103.37147 | H11: UFCF / (1 + WACC)^t
A13: Sum of PV of UFCF (FY27–FY31) | B13: =SUM(C11:G11) -> 568.97162
A15: Terminal value — Gordon Growth Method
A16: Final-year UFCF (FY2031E) | B16: =G9 -> 163.38375
A17: Terminal value (at end of FY2031) | B17: =B16*(1+B5)/(B4-B5) -> 2554.5552 | H17: TV = UFCF₅ × (1 + g) / (WACC − g)
A18: Discount factor (t = 5) | B18: =G10 -> 0.63269127
A19: PV of terminal value | B19: =B17*B18 -> 1616.2448 | H19: TV / (1 + WACC)^5
A21: Enterprise value → Equity value → Share price
A22: Enterprise value | B22: =B13+B19 -> 2185.2164 | H22: PV of forecast UFCF + PV of terminal value
A23: % of EV from terminal value | B23: =B19/B22 -> 0.73962687
A24: Plus: cash & marketable securities | B24: =Assumptions!B40 -> 146.517 | H24: Latest reported (Jun 27, 2026)
A25: Less: total debt | B25: =-Assumptions!B44 -> -84.344
A26: Equity value | B26: =B22+B24+B25 -> 2247.3894 | H26: EV + Cash − Debt
A27: Diluted shares (B) | B27: =Assumptions!B36 -> 14.667529
A28: Implied share price ($) | B28: =B26/B27 -> 153.22209 | H28: Equity value / Diluted shares
A29: Current share price ($) | B29: =Assumptions!B33 -> 336.13
A30: Upside / (downside) | B30: =B28/B29-1 -> -0.54415825
A32: Sanity checks & reverse DCF
A33: Implied terminal EV / EBITDA (TV ÷ FY31E EBITDA) | B33: =B17/'Income Statement'!K24 -> 12.051908 | H33: Cross-check: does the Gordon Growth TV imply a sensible exit multiple?
A34: Implied EV / FY2026E EBITDA | B34: =B22/'Income Statement'!F24 -> 12.852539
A35: Market EV at current price | B35: =B29*B27-Assumptions!B45 -> 4868.0235 | H35: Market cap − net cash
A36: Market EV / FY2026E EBITDA | B36: =B35/'Income Statement'!F24 -> 28.6317
A37: Terminal growth implied by current price | B37: =((B35-B13)/B18*B4-B16)/((B35-B13)/B18+B16) -> 0.070144722 | H37: Reverse DCF: solve TV = UFCF₅(1+g)/(WACC−g) for g, where TV = (Market EV − PV of UFCF) × (1+WACC)^5 → g = (TV×WACC − UFCF₅)/(TV + UFCF₅)

Sheet WACC
A1: Apple Inc. (AAPL) — WACC
A2: WACC = E/(D+E) × Cost of equity + D/(D+E) × After-tax cost of debt
A3: Input | B3: Value | C3: Source / logic
A4: Cost of equity (CAPM)
A5: Risk-free rate (10-yr US Treasury) | B5: 0.05 | C5: 10-yr Treasury ≈ 5.0% (5.01% on Sep 18, 2026; ~4.97% on Sep 21). Source: US Treasury / FRED DGS10. Match to long-dated cash flows.
A6: Beta (levered) | B6: 1.1 | C6: AAPL 5-yr monthly beta vs S&P 500 has been ~1.1–1.25 (Yahoo/Bloomberg). 1.10 used — verify on the day you present.
A7: Equity risk premium | B7: 0.0425 | C7: Damodaran implied US ERP: 4.23% at Jan 1, 2026 (damodaran.com). Rounded to 4.25%.
A8: Cost of equity | B8: =B5+B6*B7 -> 0.09675 | C8: Rf + β × ERP
A10: Cost of debt
A11: Credit spread over Treasuries | B11: 0.004 | C11: Apple is rated AA+/Aaa; its long bonds trade ~30–60bp over Treasuries. 0.40% assumed.
A12: Pre-tax cost of debt | B12: =B5+B11 -> 0.054 | C12: Rf + spread (approximates yield on Apple's bonds).
A13: Tax rate | B13: =Assumptions!K12 -> 0.17 | C13: Long-term tax rate from Assumptions.
A14: After-tax cost of debt | B14: =B12*(1-B13) -> 0.04482 | C14: Interest is tax-deductible → Kd × (1 − t).
A16: Capital structure (market values)
A17: Share price ($) | B17: =Assumptions!B33 -> 336.13
A18: Diluted shares (B) | B18: =Assumptions!B36 -> 14.667529
A19: Market value of equity (E) | B19: =B17*B18 -> 4930.1965 | C19: Market cap — use market, not book, values.
A20: Total debt (D) | B20: =Assumptions!B44 -> 84.344 | C20: Jun 27, 2026 balance sheet (book ≈ market for Apple's bonds).
A21: Total capital (D + E) | B21: =B19+B20 -> 5014.5405
A22: E / (D + E) | B22: =B19/B21 -> 0.98318011
A23: D / (D + E) | B23: =B20/B21 -> 0.016819886 | C23: Apple is ~98% equity-financed, so WACC ≈ cost of equity.
A24: WACC | B24: =B22*B8+B23*B14 -> 0.095876543

Sheet Sensitivity Analysis
A1: Apple Inc. (AAPL) — DCF Sensitivity: Implied Share Price ($)
A2: Rows = terminal growth rate, columns = WACC. Every cell re-runs the full DCF (PV of UFCF + PV of TV + cash − debt) ÷ diluted shares.
B4: WACC → | C4: Weighted average cost of capital
A5: Terminal growth ↓ | C5: 0.085 | D5: 0.09 | E5: 0.095 | F5: 0.1 | G5: 0.105
B6: 0.02 | C6: =(UFCF!C15/(1+C$5)^1+UFCF!D15/(1+C$5)^2+UFCF!E15/(1+C$5)^3+UFCF!F15/(1+C$5)^4+UFCF!G15/(1+C$5)^5+UFCF!G15*(1+$B6)/(C$5-$B6)/(1+C$5)^5+Assumptions!$B$40-Assumptions!$B$44)/Assumptions!$B$36 -> 160.42597 | D6: =(UFCF!C15/(1+D$5)^1+UFCF!D15/(1+D$5)^2+UFCF!E15/(1+D$5)^3+UFCF!F15/(1+D$5)^4+UFCF!G15/(1+D$5)^5+UFCF!G15*(1+$B6)/(D$5-$B6)/(1+D$5)^5+Assumptions!$B$40-Assumptions!$B$44)/Assumptions!$B$36 -> 149.13556 | E6: =(UFCF!C15/(1+E$5)^1+UFCF!D15/(1+E$5)^2+UFCF!E15/(1+E$5)^3+UFCF!F15/(1+E$5)^4+UFCF!G15/(1+E$5)^5+UFCF!G15*(1+$B6)/(E$5-$B6)/(1+E$5)^5+Assumptions!$B$40-Assumptions!$B$44)/Assumptions!$B$36 -> 139.35269 | F6: =(UFCF!C15/(1+F$5)^1+UFCF!D15/(1+F$5)^2+UFCF!E15/(1+F$5)^3+UFCF!F15/(1+F$5)^4+UFCF!G15/(1+F$5)^5+UFCF!G15*(1+$B6)/(F$5-$B6)/(1+F$5)^5+Assumptions!$B$40-Assumptions!$B$44)/Assumptions!$B$36 -> 130.79466 | G6: =(UFCF!C15/(1+G$5)^1+UFCF!D15/(1+G$5)^2+UFCF!E15/(1+G$5)^3+UFCF!F15/(1+G$5)^4+UFCF!G15/(1+G$5)^5+UFCF!G15*(1+$B6)/(G$5-$B6)/(1+G$5)^5+Assumptions!$B$40-Assumptions!$B$44)/Assumptions!$B$36 -> 123.24526
B7: 0.025 | C7: =(UFCF!C15/(1+C$5)^1+UFCF!D15/(1+C$5)^2+UFCF!E15/(1+C$5)^3+UFCF!F15/(1+C$5)^4+UFCF!G15/(1+C$5)^5+UFCF!G15*(1+$B7)/(C$5-$B7)/(1+C$5)^5+Assumptions!$B$40-Assumptions!$B$44)/Assumptions!$B$36 -> 170.73074 | D7: =(UFCF!C15/(1+D$5)^1+UFCF!D15/(1+D$5)^2+UFCF!E15/(1+D$5)^3+UFCF!F15/(1+D$5)^4+UFCF!G15/(1+D$5)^5+UFCF!G15*(1+$B7)/(D$5-$B7)/(1+D$5)^5+Assumptions!$B$40-Assumptions!$B$44)/Assumptions!$B$36 -> 157.80727 | E7: =(UFCF!C15/(1+E$5)^1+UFCF!D15/(1+E$5)^2+UFCF!E15/(1+E$5)^3+UFCF!F15/(1+E$5)^4+UFCF!G15/(1+E$5)^5+UFCF!G15*(1+$B7)/(E$5-$B7)/(1+E$5)^5+Assumptions!$B$40-Assumptions!$B$44)/Assumptions!$B$36 -> 146.73184 | F7: =(UFCF!C15/(1+F$5)^1+UFCF!D15/(1+F$5)^2+UFCF!E15/(1+F$5)^3+UFCF!F15/(1+F$5)^4+UFCF!G15/(1+F$5)^5+UFCF!G15*(1+$B7)/(F$5-$B7)/(1+F$5)^5+Assumptions!$B$40-Assumptions!$B$44)/Assumptions!$B$36 -> 137.13481 | G7: =(UFCF!C15/(1+G$5)^1+UFCF!D15/(1+G$5)^2+UFCF!E15/(1+G$5)^3+UFCF!F15/(1+G$5)^4+UFCF!G15/(1+G$5)^5+UFCF!G15*(1+$B7)/(G$5-$B7)/(1+G$5)^5+Assumptions!$B$40-Assumptions!$B$44)/Assumptions!$B$36 -> 128.73895
B8: 0.03 | C8: =(UFCF!C15/(1+C$5)^1+UFCF!D15/(1+C$5)^2+UFCF!E15/(1+C$5)^3+UFCF!F15/(1+C$5)^4+UFCF!G15/(1+C$5)^5+UFCF!G15*(1+$B8)/(C$5-$B8)/(1+C$5)^5+Assumptions!$B$40-Assumptions!$B$44)/Assumptions!$B$36 -> 182.9091 | D8: =(UFCF!C15/(1+D$5)^1+UFCF!D15/(1+D$5)^2+UFCF!E15/(1+D$5)^3+UFCF!F15/(1+D$5)^4+UFCF!G15/(1+D$5)^5+UFCF!G15*(1+$B8)/(D$5-$B8)/(1+D$5)^5+Assumptions!$B$40-Assumptions!$B$44)/Assumptions!$B$36 -> 167.92426 | E8: =(UFCF!C15/(1+E$5)^1+UFCF!D15/(1+E$5)^2+UFCF!E15/(1+E$5)^3+UFCF!F15/(1+E$5)^4+UFCF!G15/(1+E$5)^5+UFCF!G15*(1+$B8)/(E$5-$B8)/(1+E$5)^5+Assumptions!$B$40-Assumptions!$B$44)/Assumptions!$B$36 -> 155.24624 | F8: =(UFCF!C15/(1+F$5)^1+UFCF!D15/(1+F$5)^2+UFCF!E15/(1+F$5)^3+UFCF!F15/(1+F$5)^4+UFCF!G15/(1+F$5)^5+UFCF!G15*(1+$B8)/(F$5-$B8)/(1+F$5)^5+Assumptions!$B$40-Assumptions!$B$44)/Assumptions!$B$36 -> 144.3807 | G8: =(UFCF!C15/(1+G$5)^1+UFCF!D15/(1+G$5)^2+UFCF!E15/(1+G$5)^3+UFCF!F15/(1+G$5)^4+UFCF!G15/(1+G$5)^5+UFCF!G15*(1+$B8)/(G$5-$B8)/(1+G$5)^5+Assumptions!$B$40-Assumptions!$B$44)/Assumptions!$B$36 -> 134.96512
B9: 0.035 | C9: =(UFCF!C15/(1+C$5)^1+UFCF!D15/(1+C$5)^2+UFCF!E15/(1+C$5)^3+UFCF!F15/(1+C$5)^4+UFCF!G15/(1+C$5)^5+UFCF!G15*(1+$B9)/(C$5-$B9)/(1+C$5)^5+Assumptions!$B$40-Assumptions!$B$44)/Assumptions!$B$36 -> 197.52314 | D9: =(UFCF!C15/(1+D$5)^1+UFCF!D15/(1+D$5)^2+UFCF!E15/(1+D$5)^3+UFCF!F15/(1+D$5)^4+UFCF!G15/(1+D$5)^5+UFCF!G15*(1+$B9)/(D$5-$B9)/(1+D$5)^5+Assumptions!$B$40-Assumptions!$B$44)/Assumptions!$B$36 -> 179.8807 | E9: =(UFCF!C15/(1+E$5)^1+UFCF!D15/(1+E$5)^2+UFCF!E15/(1+E$5)^3+UFCF!F15/(1+E$5)^4+UFCF!G15/(1+E$5)^5+UFCF!G15*(1+$B9)/(E$5-$B9)/(1+E$5)^5+Assumptions!$B$40-Assumptions!$B$44)/Assumptions!$B$36 -> 165.17971 | F9: =(UFCF!C15/(1+F$5)^1+UFCF!D15/(1+F$5)^2+UFCF!E15/(1+F$5)^3+UFCF!F15/(1+F$5)^4+UFCF!G15/(1+F$5)^5+UFCF!G15*(1+$B9)/(F$5-$B9)/(1+F$5)^5+Assumptions!$B$40-Assumptions!$B$44)/Assumptions!$B$36 -> 152.74135 | G9: =(UFCF!C15/(1+G$5)^1+UFCF!D15/(1+G$5)^2+UFCF!E15/(1+G$5)^3+UFCF!F15/(1+G$5)^4+UFCF!G15/(1+G$5)^5+UFCF!G15*(1+$B9)/(G$5-$B9)/(1+G$5)^5+Assumptions!$B$40-Assumptions!$B$44)/Assumptions!$B$36 -> 142.08076
B10: 0.04 | C10: =(UFCF!C15/(1+C$5)^1+UFCF!D15/(1+C$5)^2+UFCF!E15/(1+C$5)^3+UFCF!F15/(1+C$5)^4+UFCF!G15/(1+C$5)^5+UFCF!G15*(1+$B10)/(C$5-$B10)/(1+C$5)^5+Assumptions!$B$40-Assumptions!$B$44)/Assumptions!$B$36 -> 215.38475 | D10: =(UFCF!C15/(1+D$5)^1+UFCF!D15/(1+D$5)^2+UFCF!E15/(1+D$5)^3+UFCF!F15/(1+D$5)^4+UFCF!G15/(1+D$5)^5+UFCF!G15*(1+$B10)/(D$5-$B10)/(1+D$5)^5+Assumptions!$B$40-Assumptions!$B$44)/Assumptions!$B$36 -> 194.22843 | E10: =(UFCF!C15/(1+E$5)^1+UFCF!D15/(1+E$5)^2+UFCF!E15/(1+E$5)^3+UFCF!F15/(1+E$5)^4+UFCF!G15/(1+E$5)^5+UFCF!G15*(1+$B10)/(E$5-$B10)/(1+E$5)^5+Assumptions!$B$40-Assumptions!$B$44)/Assumptions!$B$36 -> 176.91926 | F10: =(UFCF!C15/(1+F$5)^1+UFCF!D15/(1+F$5)^2+UFCF!E15/(1+F$5)^3+UFCF!F15/(1+F$5)^4+UFCF!G15/(1+F$5)^5+UFCF!G15*(1+$B10)/(F$5-$B10)/(1+F$5)^5+Assumptions!$B$40-Assumptions!$B$44)/Assumptions!$B$36 -> 162.49543 | G10: =(UFCF!C15/(1+G$5)^1+UFCF!D15/(1+G$5)^2+UFCF!E15/(1+G$5)^3+UFCF!F15/(1+G$5)^4+UFCF!G15/(1+G$5)^5+UFCF!G15*(1+$B10)/(G$5-$B10)/(1+G$5)^5+Assumptions!$B$40-Assumptions!$B$44)/Assumptions!$B$36 -> 150.2911
A12: Current share price ($) | B12: =Assumptions!B33 -> 336.13
A13: Base case (model WACC & g) | B13: =DCF!B28 -> 153.22209
A14: Base-case WACC / g | B14: =DCF!B4 -> 0.095876543 | C14: =DCF!B5 -> 0.03
A16: How to read it: moving right (higher WACC) lowers value; moving down (higher g) raises value. The spread between WACC and g drives the terminal value, which is ~70–75% of EV.

Sheet Valuation Summary
A1: Apple Inc. (AAPL) — Valuation Summary
A2: Base case | $ in billions except per share
A4: Metric | B4: Value
A5: Current share price | B5: =Assumptions!B33 -> 336.13
A6: Enterprise value ($B) | B6: =DCF!B22 -> 2185.2164
A7: Equity value ($B) | B7: =DCF!B26 -> 2247.3894
A8: Implied share price | B8: =DCF!B28 -> 153.22209
A9: Upside / (downside) | B9: =DCF!B30 -> -0.54415825
A10: WACC | B10: =DCF!B4 -> 0.095876543
A11: Terminal growth | B11: =DCF!B5 -> 0.03
A13: Key assumptions & outputs
A14: Revenue CAGR FY2026E–FY2031E | B14: =('Income Statement'!K5/'Income Statement'!F5)^(1/5)-1 -> 0.045964702
A15: Revenue CAGR FY2025A–FY2031E | B15: =('Income Statement'!K5/'Income Statement'!E5)^(1/6)-1 -> 0.062009236
A16: EBIT margin FY2025A | B16: ='Income Statement'!E14 -> 0.319708
A17: EBIT margin FY2031E | B17: ='Income Statement'!K14 -> 0.327
A18: UFCF FY2027E ($B) | B18: =UFCF!C15 -> 135.57884
A19: UFCF FY2031E ($B) | B19: =UFCF!G15 -> 163.38375
A20: UFCF CAGR FY2027E–FY2031E | B20: =(UFCF!G15/UFCF!C15)^(1/4)-1 -> 0.047741714
A21: Terminal value as % of EV | B21: =DCF!B23 -> 0.73962687
A22: Implied terminal EV/EBITDA | B22: =DCF!B33 -> 12.051908
A23: Market EV / FY2026E EBITDA | B23: =DCF!B36 -> 28.6317
A24: Terminal growth implied by current price | B24: =DCF!B37 -> 0.070144722
A25: Net cash ($B, Jun 27, 2026) | B25: =Assumptions!B45 -> 62.173
A26: Trailing P/E (price ÷ TTM diluted EPS $8.73) | B26: =Assumptions!B33/(1.85+6.88) -> 38.502864
C27: TTM EPS = Q4 FY25 $1.85 + 9M FY26 $6.88 (Apple earnings releases).
A29: Interpretation (base case)
A30: • On reasonable assumptions (≈4.6% revenue CAGR FY26–FY31E after a 14.6% FY26, EBIT margin ~32–33%, 9.6% WACC, 3% terminal growth), the DCF implies a value well below the current share price.
A31: • This is not a recommendation. It shows what the market is pricing in: at today's price and our cash flows, the model needs ~7% perpetual growth — or, holding g at 3%, a WACC of about 6.0% (≈6.9% if g = 4%).
A32: • A 5.0% risk-free rate (near a 19-year high) makes the CAPM cost of equity high. Investors appear to price Apple as a bond-like, lower-risk franchise (lower implied discount rate) and/or expect
A33: a longer runway of growth from Services, the AI-driven upgrade cycle (Siri AI, iPhone 18 / foldable) and emerging markets than a 5-year fade to 3% assumes.
A34: • Terminal value is ~70%+ of EV, so the answer is dominated by WACC and g — see the Sensitivity Analysis tab.
